INFO    : Found entry no longer exists 47634
INFO    : Now preparing local server to preview your project directory `/Users/danaernst/GitHub/IntroToProofViaIBL`.
INFO    :   (Reminder: use `pretext deploy` to deploy your built project to a public
INFO    :   GitHub Pages site that can be shared with readers who cannot access your
INFO    :   personal computer.)
INFO    : 
INFO    : starting server ...
INFO    : setting up ...
INFO    : values set...
INFO    : adding server entry
INFO    : There are 10 or more servers on file. Cleaning up ...
INFO    : Found entry no longer exists 47634
INFO    : Terminating 47634
INFO    : Terminate failed for 47634.
ERROR   : process PID not found (pid=47634)
Traceback (most recent call last):
  File "/Users/danaernst/Library/Python/3.9/lib/python/site-packages/pretext/server.py", line 76, in terminate
    psutil.Process(self.pid).terminate()
  File "/Users/danaernst/Library/Python/3.9/lib/python/site-packages/psutil/__init__.py", line 317, in __init__
    self._init(pid)
  File "/Users/danaernst/Library/Python/3.9/lib/python/site-packages/psutil/__init__.py", line 363, in _init
    raise NoSuchProcess(pid, msg=msg) from None
psutil.NoSuchProcess: process PID not found (pid=47634)
ERROR   : View encountered an error.  Please report this: process 48103 with laddr 
ERROR   : View encountered an error.  Please report this: process 48103 with laddr 
ERROR   : View encountered an error.  Please report this: process 48103 with laddr 
INFO    : Found server at localhost:8129
INFO    : Found entry no longer exists 5533
INFO    : Terminating 5533
INFO    : Terminate failed for 5533.
ERROR   : process PID not found (pid=5533)
Traceback (most recent call last):
  File "/Users/danaernst/Library/Python/3.9/lib/python/site-packages/pretext/server.py", line 76, in terminate
    psutil.Process(self.pid).terminate()
  File "/Users/danaernst/Library/Python/3.9/lib/python/site-packages/psutil/__init__.py", line 317, in __init__
    self._init(pid)
  File "/Users/danaernst/Library/Python/3.9/lib/python/site-packages/psutil/__init__.py", line 363, in _init
    raise NoSuchProcess(pid, msg=msg) from None
psutil.NoSuchProcess: process PID not found (pid=5533)
INFO    : Found entry no longer exists 47634
INFO    : Terminating 47634
INFO    : Terminate failed for 47634.
ERROR   : process PID not found (pid=47634)
Traceback (most recent call last):
  File "/Users/danaernst/Library/Python/3.9/lib/python/site-packages/pretext/server.py", line 76, in terminate
    psutil.Process(self.pid).terminate()
  File "/Users/danaernst/Library/Python/3.9/lib/python/site-packages/psutil/__init__.py", line 317, in __init__
    self._init(pid)
  File "/Users/danaernst/Library/Python/3.9/lib/python/site-packages/psutil/__init__.py", line 363, in _init
    raise NoSuchProcess(pid, msg=msg) from None
psutil.NoSuchProcess: process PID not found (pid=47634)
INFO    : Found entry no longer exists 47634
INFO    : Terminating 47634
INFO    : Terminate failed for 47634.
ERROR   : process PID not found (pid=47634)
Traceback (most recent call last):
  File "/Users/danaernst/Library/Python/3.9/lib/python/site-packages/pretext/server.py", line 76, in terminate
    psutil.Process(self.pid).terminate()
  File "/Users/danaernst/Library/Python/3.9/lib/python/site-packages/psutil/__init__.py", line 317, in __init__
    self._init(pid)
  File "/Users/danaernst/Library/Python/3.9/lib/python/site-packages/psutil/__init__.py", line 363, in _init
    raise NoSuchProcess(pid, msg=msg) from None
psutil.NoSuchProcess: process PID not found (pid=47634)
INFO    : Found entry no longer exists 47634
INFO    : Terminating 47634
INFO    : Terminate failed for 47634.
ERROR   : process PID not found (pid=47634)
Traceback (most recent call last):
  File "/Users/danaernst/Library/Python/3.9/lib/python/site-packages/pretext/server.py", line 76, in terminate
    psutil.Process(self.pid).terminate()
  File "/Users/danaernst/Library/Python/3.9/lib/python/site-packages/psutil/__init__.py", line 317, in __init__
    self._init(pid)
  File "/Users/danaernst/Library/Python/3.9/lib/python/site-packages/psutil/__init__.py", line 363, in _init
    raise NoSuchProcess(pid, msg=msg) from None
psutil.NoSuchProcess: process PID not found (pid=47634)
INFO    : Found entry no longer exists 47634
INFO    : Terminating 47634
INFO    : Terminate failed for 47634.
ERROR   : process PID not found (pid=47634)
Traceback (most recent call last):
  File "/Users/danaernst/Library/Python/3.9/lib/python/site-packages/pretext/server.py", line 76, in terminate
    psutil.Process(self.pid).terminate()
  File "/Users/danaernst/Library/Python/3.9/lib/python/site-packages/psutil/__init__.py", line 317, in __init__
    self._init(pid)
  File "/Users/danaernst/Library/Python/3.9/lib/python/site-packages/psutil/__init__.py", line 363, in _init
    raise NoSuchProcess(pid, msg=msg) from None
psutil.NoSuchProcess: process PID not found (pid=47634)
INFO    : Found entry no longer exists 47634
INFO    : Terminating 47634
INFO    : Terminate failed for 47634.
ERROR   : process PID not found (pid=47634)
Traceback (most recent call last):
  File "/Users/danaernst/Library/Python/3.9/lib/python/site-packages/pretext/server.py", line 76, in terminate
    psutil.Process(self.pid).terminate()
  File "/Users/danaernst/Library/Python/3.9/lib/python/site-packages/psutil/__init__.py", line 317, in __init__
    self._init(pid)
  File "/Users/danaernst/Library/Python/3.9/lib/python/site-packages/psutil/__init__.py", line 363, in _init
    raise NoSuchProcess(pid, msg=msg) from None
psutil.NoSuchProcess: process PID not found (pid=47634)
INFO    : Found entry no longer exists 47634
INFO    : Terminating 47634
INFO    : Terminate failed for 47634.
ERROR   : process PID not found (pid=47634)
Traceback (most recent call last):
  File "/Users/danaernst/Library/Python/3.9/lib/python/site-packages/pretext/server.py", line 76, in terminate
    psutil.Process(self.pid).terminate()
  File "/Users/danaernst/Library/Python/3.9/lib/python/site-packages/psutil/__init__.py", line 317, in __init__
    self._init(pid)
  File "/Users/danaernst/Library/Python/3.9/lib/python/site-packages/psutil/__init__.py", line 363, in _init
    raise NoSuchProcess(pid, msg=msg) from None
psutil.NoSuchProcess: process PID not found (pid=47634)
ERROR   : View encountered an error.  Please report this: process 8990 with laddr 
ERROR   : View encountered an error.  Please report this: process 8990 with laddr 
ERROR   : View encountered an error.  Please report this: process 8990 with laddr 
INFO    : Found server at localhost:8128
INFO    : Added server entry 653774bce7 8990 8128 localhost

INFO    : Starting the server
INFO    : Server will soon be available at http://localhost:8128
INFO    : Opening browser for target `web` at http://localhost:8128/output/web
